Workbook

Sheet DASH_FEED
A1: DASH_FEED — Dashboard data feed (auto-linked; edit blue cells only)
A3: [META]
A4: client_name | B4: Meadowbrook Animal Hospital
A5: period_py_label | B5: TTM Jun-25
A6: period_cy_label | B6: TTM Jun-26
A7: purchase_price | B7: 3750000
A8: location | B8: Franklin, Tennessee
A10: [KPIS]
A11: revenue_py | B11: ='Monthly IS'!Z9 -> 2410318
A12: revenue_cy | B12: ='Monthly IS'!AA9 -> 2504921
A13: cogs_py | B13: ='Monthly IS'!Z15 -> 602580
A14: cogs_cy | B14: ='Monthly IS'!AA15 -> 651279
A15: adj_ebitda_py | B15: =C33 -> 255490
A16: adj_ebitda_cy | B16: =D33 -> 249035
A17: adj_margin_py | B17: =B15/B11 -> 0.10599846
A18: adj_margin_cy | B18: =B16/B12 -> 0.099418305
A19: implied_multiple_cy | B19: =B7/B16 -> 15.058124
A22: [BRIDGE]
A23: line | B23: ref | C23: value_py | D23: value_cy
A24: Reported EBITDA | C24: ='Monthly IS'!Z26 -> 61240 | D24: ='Monthly IS'!AA26 -> 38115
A25: Nonrecurring Expenses | B25: A | C25: 38900 | D25: 42350
A26: DVM Compensation | B26: B | C26: 152300 | D26: 168420
A27: Proforma Insurance | B27: C | C27: -4200 | D27: -3850
A28: Rent Normalization | B28: D | C28: -18600 | D28: -6200
A29: Family on Payroll | B29: E | C29: 7450 | D29: 8100
A30: Non-recurring Legal | B30: F | C30: 5600 | D30: 2100
A31: Loss on Disposal | B31: G | C31: 12800 | D31: 0
A32: Seller Adjusted EBITDA | C32: =C24+C25 -> 100140 | D32: =D24+D25 -> 80465
A33: Diligence Adjusted EBITDA | C33: =C32+SUM(C26:C31) -> 255490 | D33: =D32+SUM(D26:D31) -> 249035
A44: [MARGIN_SERIES] | D44: [SGA_MIX]
A45: month | B45: gross_margin_pct | D45: category | E45: adjusted_value_cy
A46: Jul | B46: 0.742 | D46: Labor - DVM | E46: 538200
A47: Aug | B47: 0.718 | D47: Labor - Staff | E47: 592400
A48: Sep | B48: 0.735 | D48: Labor & Fringe | E48: 174800
A49: Oct | B49: 0.709 | D49: Facility & Equip | E49: 138900
A50: Nov | B50: 0.751 | D50: Admin | E50: 80707
A51: Dec | B51: 0.688 | D51: Fee/Collection | E51: 58200
A52: Jan | B52: 0.726 | D52: Marketing | E52: 21400
A53: Feb | B53: 0.744 | D53: D&A | E53: 63100
A54: Mar | B54: 0.701
...

Sheet Monthly IS
A1: armanino
A2: Meadowbrook Animal Hospital — Monthly Income Statement (As Presented)
A3: All figures illustrative / fictional • $ actuals
A4: Account | B4: Jul-24 | C4: Aug-24 | D4: Sep-24 | E4: Oct-24 | F4: Nov-24 | G4: Dec-24 | H4: Jan-25 | I4: Feb-25 | J4: Mar-25 | K4: Apr-25 | L4: May-25 | M4: Jun-25 | N4: Jul-25 | O4: Aug-25 | P4: Sep-25 | Q4: Oct-25 | R4: Nov-25 | S4: Dec-25 | T4: Jan-26 | U4: Feb-26 | V4: Mar-26 | W4: Apr-26 | X4: May-26 | Y4: Jun-26 | Z4: TTM Jun-25 | AA4: TTM Jun-26
A5: Revenue
A6: Professional Fees | B6: 156189 | C6: 163902 | D6: 160045 | E6: 169686 | F6: 152332 | G6: 134978 | H6: 158117 | I6: 161974 | J6: 171614 | K6: 165830 | L6: 169686 | M6: 163902 | N6: 162319 | O6: 170334 | P6: 166326 | Q6: 176346 | R6: 158311 | S6: 140275 | T6: 164323 | U6: 168330 | V6: 178350 | W6: 172338 | X6: 176346 | Y6: 170335 | Z6: =SUM(B6:M6) -> 1928255 | AA6: =SUM(N6:Y6) -> 2003933
A7: Retail & Pharmacy | B7: 33190 | C7: 34829 | D7: 34010 | E7: 36058 | F7: 32371 | G7: 28683 | H7: 33600 | I7: 34419 | J7: 36468 | K7: 35239 | L7: 36058 | M7: 34829 | N7: 34493 | O7: 36196 | P7: 35344 | Q7: 37474 | R7: 33641 | S7: 29808 | T7: 34919 | U7: 35770 | V7: 37899 | W7: 36622 | X7: 37474 | Y7: 36196 | Z7: =SUM(B7:M7) -> 409754 | AA7: =SUM(N7:Y7) -> 425836
A8: Other Income | B8: 5857 | C8: 6146 | D8: 6001 | E8: 6364 | F8: 5712 | G8: 5061 | H8: 5929 | I8: 6074 | J8: 6436 | K8: 6218 | L8: 6364 | M8: 6147 | N8: 6087 | O8: 6388 | P8: 6238 | Q8: 6613 | R8: 5937 | S8: 5261 | T8: 6162 | U8: 6313 | V8: 6689 | W8: 6463 | X8: 6613 | Y8: 6388 | Z8: =SUM(B8:M8) -> 72309 | AA8: =SUM(N8:Y8) -> 75152
A9: Total Revenue | B9: =SUM(B6:B8) -> 195236 | C9: =SUM(C6:C8) -> 204877 | D9: =SUM(D6:D8) -> 200056 | E9: =SUM(E6:E8) -> 212108 | F9: =SUM(F6:F8) -> 190415 | G9: =SUM(G6:G8) -> 168722 | H9: =SUM(H6:H8) -> 197646 | I9: =SUM(I6:I8) -> 202467 | ... Y9: =SUM(Y6:Y8) -> 212919 | Z9: =SUM(B9:M9) -> 2410318 | AA9: =SUM(N9:Y9) -> 2504921
A10: Cost of Products
A11: Drugs & Medical Supplies | B11: 26845 | C11: 28170 | D11: 27508 | E11: 29165 | F11: 26182 | G11: 23200 | H11: 27177 | I11: 27839 | J11: 29497 | K11: 28502 | L11: 29165 | M11: 28170 | N11: 29015 | O11: 30447 | P11: 29731 | Q11: 31522 | R11: 28298 | S11: 25075 | T11: 29373 | U11: 30089 | V11: 31880 | W11: 30806 | X11: 31522 | Y11: 30446 | Z11: =SUM(B11:M11) -> 331420 | AA11: =SUM(N11:Y11) -> 358204
A12: Prescription Diet & Food | B12: 9762 | C12: 10244 | D12: 10003 | E12: 10605 | F12: 9521 | G12: 8436 | H12: 9882 | I12: 10123 | J12: 10726 | K12: 10364 | L12: 10605 | M12: 10244 | N12: 10551 | O12: 11072 | P12: 10811 | Q12: 11463 | R12: 10290 | S12: 9118 | T12: 10681 | U12: 10941 | V12: 11593 | W12: 11202 | X12: 11463 | Y12: 11071 | Z12: =SUM(B12:M12) -> 120515 | AA12: =SUM(N12:Y12) -> 130256
A13: Laboratory & Outside Services | B13: 7321 | C13: 7683 | D13: 7502 | E13: 7954 | F13: 7141 | G13: 6327 | H13: 7412 | I13: 7593 | J13: 8044 | K13: 7773 | L13: 7954 | M13: 7683 | N13: 7913 | O13: 8304 | P13: 8108 | Q13: 8597 | R13: 7718 | S13: 6838 | T13: 8011 | U13: 8206 | V13: 8695 | W13: 8402 | X13: 8597 | Y13: 8304 | Z13: =SUM(B13:M13) -> 90387 | AA13: =SUM(N13:Y13) -> 97693
A14: Vaccines | B14: 4881 | C14: 5122 | D14: 5001 | E14: 5303 | F14: 4760 | G14: 4218 | H14: 4941 | I14: 5062 | J14: 5363 | K14: 5183 | L14: 5303 | M14: 5121 | N14: 5275 | O14: 5536 | P14: 5406 | Q14: 5731 | R14: 5145 | S14: 4559 | T14: 5340 | U14: 5471 | V14: 5796 | W14: 5600 | X14: 5731 | Y14: 5536 | Z14: =SUM(B14:M14) -> 60258 | AA14: =SUM(N14:Y14) -> 65126
A15: Total Cost of Products | B15: =SUM(B11:B14) -> 48809 | C15: =SUM(C11:C14) -> 51219 | D15: =SUM(D11:D14) -> 50014 | E15: =SUM(E11:E14) -> 53027 | F15: =SUM(F11:F14) -> 47604 | G15: =SUM(G11:G14) -> 42181 | H15: =SUM(H11:H14) -> 49412 | I15: =SUM(I11:I14) -> 50617 | ... Y15: =SUM(Y11:Y14) -> 55357 | Z15: =SUM(B15:M15) -> 602580 | AA15: =SUM(N15:Y15) -> 651279
A16: Gross Profit | B16: =B9-B15 -> 146427 | C16: =C9-C15 -> 153658 | D16: =D9-D15 -> 150042 | E16: =E9-E15 -> 159081 | F16: =F9-F15 -> 142811 | G16: =G9-G15 -> 126541 | H16: =H9-H15 -> 148234 | I16: =I9-I15 -> 151850 | ... Y16: =Y9-Y15 -> 157562 | Z16: =SUM(B16:M16) -> 1807738 | AA16: =SUM(N16:Y16) -> 1853642
A17: Operating Expenses
A18: Labor - DVM | B18: 55060 | C18: 57779 | D18: 56419 | E18: 59818 | F18: 53700 | G18: 47583 | H18: 55740 | I18: 57099 | J18: 60498 | K18: 58459 | L18: 59818 | M18: 57780 | N18: 57236 | O18: 60063 | P18: 58649 | Q18: 62183 | R18: 55823 | S18: 49463 | T18: 57943 | U18: 59356 | V18: 62889 | W18: 60769 | X18: 62183 | Y18: 60063 | Z18: =SUM(B18:M18) -> 679753 | AA18: =SUM(N18:Y18) -> 706620
A19: Labor - Staff | B19: 46791 | C19: 49102 | D19: 47946 | E19: 50835 | F19: 45636 | G19: 40437 | H19: 47369 | I19: 48524 | J19: 51412 | K19: 49679 | L19: 50835 | M19: 49102 | N19: 48640 | O19: 51043 | P19: 49842 | Q19: 52844 | R19: 47440 | S19: 42035 | T19: 49241 | U19: 50442 | V19: 53444 | W19: 51643 | X19: 52844 | Y19: 51042 | Z19: =SUM(B19:M19) -> 577668 | AA19: =SUM(N19:Y19) -> 600500
A20: Labor & Fringe | B20: 13620 | C20: 14293 | D20: 13957 | E20: 14798 | F20: 13284 | G20: 11771 | H20: 13789 | I20: 14125 | J20: 14966 | K20: 14461 | L20: 14798 | M20: 14292 | N20: 14159 | O20: 14858 | P20: 14508 | Q20: 15382 | R20: 13809 | S20: 12236 | T20: 14334 | U20: 14683 | V20: 15557 | W20: 15033 | X20: 15382 | Y20: 14859 | Z20: =SUM(B20:M20) -> 168154 | AA20: =SUM(N20:Y20) -> 174800
A21: Facility & Equipment | B21: 10040 | C21: 10536 | D21: 10288 | E21: 10908 | F21: 9792 | G21: 8677 | H21: 10164 | I21: 10412 | J21: 11032 | K21: 10660 | L21: 10908 | M21: 10534 | N21: 10437 | O21: 10952 | P21: 10695 | Q21: 11339 | R21: 10179 | S21: 9020 | T21: 10566 | U21: 10823 | V21: 11468 | W21: 11081 | X21: 11339 | Y21: 10951 | Z21: =SUM(B21:M21) -> 123951 | AA21: =SUM(N21:Y21) -> 128850
A22: Administrative | B22: 9752 | C22: 10234 | D22: 9993 | E22: 10595 | F22: 9511 | G22: 8428 | H22: 9873 | I22: 10113 | J22: 10715 | K22: 10354 | L22: 10595 | M22: 10235 | N22: 10138 | O22: 10638 | P22: 10388 | Q22: 11014 | R22: 9887 | S22: 8761 | T22: 10263 | U22: 10513 | V22: 11139 | W22: 10764 | X22: 11014 | Y22: 10638 | Z22: =SUM(B22:M22) -> 120398 | AA22: =SUM(N22:Y22) -> 125157
A23: Fee Income & Collection | B23: 4535 | C23: 4759 | D23: 4647 | E23: 4927 | F23: 4423 | G23: 3919 | H23: 4591 | I23: 4703 | J23: 4983 | K23: 4815 | L23: 4927 | M23: 4758 | N23: 4714 | O23: 4947 | P23: 4831 | Q23: 5122 | R23: 4598 | S23: 4074 | T23: 4772 | U23: 4889 | V23: 5180 | W23: 5005 | X23: 5122 | Y23: 4946 | Z23: =SUM(B23:M23) -> 55987 | AA23: =SUM(N23:Y23) -> 58200
A24: Marketing | B24: 1668 | C24: 1750 | D24: 1709 | E24: 1812 | F24: 1626 | G24: 1441 | H24: 1688 | I24: 1729 | J24: 1832 | K24: 1770 | L24: 1812 | M24: 1750 | N24: 1733 | O24: 1819 | P24: 1776 | Q24: 1883 | R24: 1691 | S24: 1498 | T24: 1755 | U24: 1798 | V24: 1905 | W24: 1840 | X24: 1883 | Y24: 1819 | Z24: =SUM(B24:M24) -> 20587 | AA24: =SUM(N24:Y24) -> 21400
A25: Total Operating Expenses | B25: =SUM(B18:B24) -> 141466 | C25: =SUM(C18:C24) -> 148453 | D25: =SUM(D18:D24) -> 144959 | E25: =SUM(E18:E24) -> 153693 | F25: =SUM(F18:F24) -> 137972 | G25: =SUM(G18:G24) -> 122256 | H25: =SUM(H18:H24) -> 143214 | I25: =SUM(I18:I24) -> 146705 | ... Y25: =SUM(Y18:Y24) -> 154318 | Z25: =SUM(B25:M25) -> 1746498 | AA25: =SUM(N25:Y25) -> 1815527
A26: EBITDA | B26: =B16-B25 -> 4961 | C26: =C16-C25 -> 5205 | D26: =D16-D25 -> 5083 | E26: =E16-E25 -> 5388 | F26: =F16-F25 -> 4839 | G26: =G16-G25 -> 4285 | H26: =H16-H25 -> 5020 | I26: =I16-I25 -> 5145 | ... Y26: =Y16-Y25 -> 3244 | Z26: =SUM(B26:M26) -> 61240 | AA26: =SUM(N26:Y26) -> 38115
A27: Depreciation & Amortization | B27: 4860 | C27: 5100 | D27: 4980 | E27: 5280 | F27: 4740 | G27: 4200 | H27: 4920 | I27: 5040 | J27: 5340 | K27: 5160 | L27: 5280 | M27: 5100 | N27: 5111 | O27: 5364 | P27: 5237 | Q27: 5553 | R27: 4985 | S27: 4417 | T27: 5174 | U27: 5300 | V27: 5616 | W27: 5427 | X27: 5553 | Y27: 5363 | Z27: =SUM(B27:M27) -> 60000 | AA27: =SUM(N27:Y27) -> 63100
A28: Interest Expense | B28: 113 | C28: 119 | D28: 116 | E28: 123 | F28: 111 | G28: 98 | H28: 115 | I28: 118 | J28: 125 | K28: 120 | L28: 123 | M28: 119 | N28: 126 | O28: 133 | P28: 129 | Q28: 137 | R28: 123 | S28: 109 | T28: 128 | U28: 131 | V28: 139 | W28: 134 | X28: 137 | Y28: 134 | Z28: =SUM(B28:M28) -> 1400 | AA28: =SUM(N28:Y28) -> 1560
A29: Other Income/(Expense) | B29: 243 | C29: 255 | D29: 249 | E29: 264 | F29: 237 | G29: 210 | H29: 246 | I29: 252 | J29: 267 | K29: 258 | L29: 264 | M29: 255 | N29: 202 | O29: 213 | P29: 208 | Q29: 220 | R29: 198 | S29: 175 | T29: 205 | U29: 210 | V29: 222 | W29: 215 | X29: 220 | Y29: 212 | Z29: =SUM(B29:M29) -> 3000 | AA29: =SUM(N29:Y29) -> 2500
A30: Net Income | B30: =B16-B25-B27-B28+B29 -> 231 | C30: =C16-C25-C27-C28+C29 -> 241 | D30: =D16-D25-D27-D28+D29 -> 236 | E30: =E16-E25-E27-E28+E29 -> 249 | F30: =F16-F25-F27-F28+F29 -> 225 | G30: =G16-G25-G27-G28+G29 -> 197 | H30: =H16-H25-H27-H28+H29 -> 231 | I30: =I16-I25-I27-I28+I29 -> 239 | ... Y30: =Y16-Y25-Y27-Y28+Y29 -> -2041 | Z30: =SUM(B30:M30) -> 2840 | AA30: =SUM(N30:Y30) -> -24045

Sheet Cover
A1: armanino
A4: Quality of Earnings — Databook (DRAFT)
A6: Prepared for:
A7: =DASH_FEED!B4 -> Meadowbrook Animal Hospital
A8: =DASH_FEED!B8 -> Franklin, Tennessee
A10: Periods presented:
A11: =""&DASH_FEED!B5&" and "&DASH_FEED!B6 -> TTM Jun-25 and TTM Jun-26
A13: Prepared by: Armanino LLP — Transaction Advisory
A14: Illustrative / fictional — safe for development & demo.

Sheet Report
A1: armanino
A2: Report
A3: Illustrative / fictional
A5: ="Re: "&DASH_FEED!B4 -> Re: Meadowbrook Animal Hospital
A7: At your request, we performed certain due diligence procedures in connection with the
A8: potential acquisition of the Company. The schedules are based on information provided by the
A9: Company and have not been independently verified; our procedures do not constitute an audit.
A11: These schedules are solely for the acquirer's management and advisors.
A14: Armanino LLP

Sheet Executive Summary
A1: armanino
A2: Executive Summary
A3: Illustrative / fictional
A5: Metric | B5: =DASH_FEED!B5 -> TTM Jun-25 | C5: =DASH_FEED!B6 -> TTM Jun-26
A6: Revenue | B6: =DASH_FEED!B11 -> 2410318 | C6: =DASH_FEED!B12 -> 2504921
A7: Diligence Adjusted EBITDA | B7: =DASH_FEED!B15 -> 255490 | C7: =DASH_FEED!B16 -> 249035
A8: Adjusted EBITDA Margin | B8: =DASH_FEED!B17 -> 0.10599846 | C8: =DASH_FEED!B18 -> 0.099418305
A9: Purchase Price (cash) | B9: =DASH_FEED!B7 -> 3750000 | C9: =DASH_FEED!B7 -> 3750000
A10: Implied Multiple | C10: =DASH_FEED!B19 -> 15.058124

Sheet Key Findings
A1: armanino
A2: Key Findings
A3: Illustrative / fictional
A5: =DASH_FEED!A61 -> • Dr. Alicia Monroe (owner) transitions to 21% of production post-close; comp normalized in Adjustment B.
A6: =DASH_FEED!A62 -> • Gross margin declined ~2.1% Jun-25 to Jun-26, driven by vendor price increases and higher relief-vet usage.
A7: =DASH_FEED!A63 -> • Buyer valuation revised: FY25 Adjusted EBITDA moved from $300K to $235K after a ~$85K revenue reclassification.
A8: =DASH_FEED!A64 -> • Cash proof analysis for the twelve months ended Jun-26 nets to a $0 variance.
A9: =DASH_FEED!A65 -> • Practice offers health and dental; go-forward buyer adds vision and a 2% 401(k) match.

Sheet EBITDA Analysis
A1: armanino
A2: EBITDA Analysis
A3: Illustrative / fictional
A5: Line | B5: Ref | C5: TTM Jun-25 | D5: % Rev | E5: TTM Jun-26 | F5: % Rev
A6: Reported EBITDA | C6: =DASH_FEED!C24 -> 61240 | D6: =C6/DASH_FEED!B11 -> 0.025407436 | E6: =DASH_FEED!D24 -> 38115 | F6: =E6/DASH_FEED!B12 -> 0.015216049
A7: Nonrecurring Expenses | B7: A | C7: =DASH_FEED!C25 -> 38900 | D7: =C7/DASH_FEED!B11 -> 0.016138949 | E7: =DASH_FEED!D25 -> 42350 | F7: =E7/DASH_FEED!B12 -> 0.016906721
A8: DVM Compensation | B8: B | C8: =DASH_FEED!C26 -> 152300 | D8: =C8/DASH_FEED!B11 -> 0.063186683 | E8: =DASH_FEED!D26 -> 168420 | F8: =E8/DASH_FEED!B12 -> 0.067235653
A9: Proforma Insurance | B9: C | C9: =DASH_FEED!C27 -> -4200 | D9: =C9/DASH_FEED!B11 -> -0.0017425087 | E9: =DASH_FEED!D27 -> -3850 | F9: =E9/DASH_FEED!B12 -> -0.0015369746
A10: Rent Normalization | B10: D | C10: =DASH_FEED!C28 -> -18600 | D10: =C10/DASH_FEED!B11 -> -0.0077168241 | E10: =DASH_FEED!D28 -> -6200 | F10: =E10/DASH_FEED!B12 -> -0.002475128
A11: Family on Payroll | B11: E | C11: =DASH_FEED!C29 -> 7450 | D11: =C11/DASH_FEED!B11 -> 0.0030908785 | E11: =DASH_FEED!D29 -> 8100 | F11: =E11/DASH_FEED!B12 -> 0.0032336349
A12: Non-recurring Legal | B12: F | C12: =DASH_FEED!C30 -> 5600 | D12: =C12/DASH_FEED!B11 -> 0.0023233449 | E12: =DASH_FEED!D30 -> 2100 | F12: =E12/DASH_FEED!B12 -> 0.00083834979
A13: Loss on Disposal | B13: G | C13: =DASH_FEED!C31 -> 12800 | D13: =C13/DASH_FEED!B11 -> 0.0053105026 | E13: =DASH_FEED!D31 -> 0 | F13: =E13/DASH_FEED!B12 -> 0
A14: Seller Adjusted EBITDA | C14: =DASH_FEED!C32 -> 100140 | D14: =C14/DASH_FEED!B11 -> 0.041546385 | E14: =DASH_FEED!D32 -> 80465 | F14: =E14/DASH_FEED!B12 -> 0.03212277
A15: Diligence Adjusted EBITDA | C15: =DASH_FEED!C33 -> 255490 | D15: =C15/DASH_FEED!B11 -> 0.10599846 | E15: =DASH_FEED!D33 -> 249035 | F15: =E15/DASH_FEED!B12 -> 0.099418305

Sheet QofE
A1: armanino
A2: Quality of Earnings
A3: Illustrative / fictional
A5: Quality of Earnings | B5: TTM Jun-25 | C5: TTM Jun-26
A6: Revenue | B6: ='Monthly IS'!Z9 -> 2410318 | C6: ='Monthly IS'!AA9 -> 2504921
A7: Cost of Products | B7: ='Monthly IS'!Z15 -> 602580 | C7: ='Monthly IS'!AA15 -> 651279
A8: Gross Profit | B8: ='Monthly IS'!Z16 -> 1807738 | C8: ='Monthly IS'!AA16 -> 1853642
A9: Labor - DVM | B9: ='Monthly IS'!Z18 -> 679753 | C9: ='Monthly IS'!AA18 -> 706620
A10: Labor - Staff | B10: ='Monthly IS'!Z19 -> 577668 | C10: ='Monthly IS'!AA19 -> 600500
A11: Labor & Fringe | B11: ='Monthly IS'!Z20 -> 168154 | C11: ='Monthly IS'!AA20 -> 174800
A12: Facility & Equipment | B12: ='Monthly IS'!Z21 -> 123951 | C12: ='Monthly IS'!AA21 -> 128850
A13: Administrative | B13: ='Monthly IS'!Z22 -> 120398 | C13: ='Monthly IS'!AA22 -> 125157
A14: Fee Income & Collection | B14: ='Monthly IS'!Z23 -> 55987 | C14: ='Monthly IS'!AA23 -> 58200
A15: Marketing | B15: ='Monthly IS'!Z24 -> 20587 | C15: ='Monthly IS'!AA24 -> 21400
A16: Total Operating Expenses | B16: ='Monthly IS'!Z25 -> 1746498 | C16: ='Monthly IS'!AA25 -> 1815527
A17: EBITDA | B17: ='Monthly IS'!Z26 -> 61240 | C17: ='Monthly IS'!AA26 -> 38115

Sheet Adj FS
A1: armanino
A2: Adjusted Financial Statements
A3: Illustrative / fictional
A5: Metric | B5: TTM Jun-25 | C5: TTM Jun-26
A6: Revenue | B6: =DASH_FEED!B11 -> 2410318 | C6: =DASH_FEED!B12 -> 2504921
A7: Cost of Products | B7: =DASH_FEED!B13 -> 602580 | C7: =DASH_FEED!B14 -> 651279
A8: Gross Profit | B8: =B6-B7 -> 1807738 | C8: =C6-C7 -> 1853642
A9: Diligence Adjusted EBITDA | B9: =DASH_FEED!B15 -> 255490 | C9: =DASH_FEED!B16 -> 249035
A10: Adjusted EBITDA Margin | B10: =B9/B6 -> 0.10599846 | C10: =C9/C6 -> 0.099418305

Sheet SG&A Analysis
A1: armanino
A2: SG&A Analysis (TTM Jun-26)
A3: Illustrative / fictional • As Presented → Adjusted
A5: Category | B5: As Presented | C5: Adjustment | D5: Adjusted | E5: Check
A6: Labor - DVM | B6: ='Monthly IS'!AA18 -> 706620 | C6: 168420 | D6: =B6-C6 -> 538200 | E6: =D6-DASH_FEED!E46 -> 0
A7: Labor - Staff | B7: ='Monthly IS'!AA19 -> 600500 | C7: 8100 | D7: =B7-C7 -> 592400 | E7: =D7-DASH_FEED!E47 -> 0
A8: Labor & Fringe | B8: ='Monthly IS'!AA20 -> 174800 | C8: 0 | D8: =B8-C8 -> 174800 | E8: =D8-DASH_FEED!E48 -> 0
A9: Facility & Equipment | B9: ='Monthly IS'!AA21 -> 128850 | C9: -10050 | D9: =B9-C9 -> 138900 | E9: =D9-DASH_FEED!E49 -> 0
A10: Administrative | B10: ='Monthly IS'!AA22 -> 125157 | C10: 44450 | D10: =B10-C10 -> 80707 | E10: =D10-DASH_FEED!E50 -> 0
A11: Fee Income & Collection | B11: ='Monthly IS'!AA23 -> 58200 | C11: 0 | D11: =B11-C11 -> 58200 | E11: =D11-DASH_FEED!E51 -> 0
A12: Marketing | B12: ='Monthly IS'!AA24 -> 21400 | C12: 0 | D12: =B12-C12 -> 21400 | E12: =D12-DASH_FEED!E52 -> 0
A13: Total (excl D&A) | B13: =SUM(B6:B12) -> 1815527 | C13: =SUM(C6:C12) -> 210920 | D13: =SUM(D6:D12) -> 1604607

Sheet Payroll Analysis
A1: armanino
A2: Payroll Analysis
A3: Illustrative / fictional
A5: Staff Employees | B5: TTM Jun-25 | C5: TTM Jun-26
A6: Staff Wages | B6: ='Monthly IS'!Z19 -> 577668 | C6: ='Monthly IS'!AA19 -> 600500
A7: Staff Wages as % of Revenue | B7: =B6/DASH_FEED!B11 -> 0.23966464 | C7: =C6/DASH_FEED!B12 -> 0.23972812
A8: Hours | B8: 18450 | C8: 19120
A10: Owner / DVM
A11: DVM Wages (as presented) | B11: ='Monthly IS'!Z18 -> 679753 | C11: ='Monthly IS'!AA18 -> 706620
A12: DVM Wages (adjusted) | C12: =DASH_FEED!E46 -> 538200
A13: Go-Forward Owner Comp (21% of production) | C13: =0.21*DASH_FEED!B12 -> 526033.41

Sheet Mthly Rev and Margin Trends
A1: armanino
A2: Monthly Revenue & Margin Trend (TTM Jun-26)
A3: Illustrative / fictional
A5: Month | B5: Revenue | C5: Gross Margin %
A6: Jul-25 | B6: ='Monthly IS'!N9 -> 202899 | C6: =DASH_FEED!B46 -> 0.742
A7: Aug-25 | B7: ='Monthly IS'!O9 -> 212918 | C7: =DASH_FEED!B47 -> 0.718
A8: Sep-25 | B8: ='Monthly IS'!P9 -> 207908 | C8: =DASH_FEED!B48 -> 0.735
A9: Oct-25 | B9: ='Monthly IS'!Q9 -> 220433 | C9: =DASH_FEED!B49 -> 0.709
A10: Nov-25 | B10: ='Monthly IS'!R9 -> 197889 | C10: =DASH_FEED!B50 -> 0.751
A11: Dec-25 | B11: ='Monthly IS'!S9 -> 175344 | C11: =DASH_FEED!B51 -> 0.688
A12: Jan-26 | B12: ='Monthly IS'!T9 -> 205404 | C12: =DASH_FEED!B52 -> 0.726
A13: Feb-26 | B13: ='Monthly IS'!U9 -> 210413 | C13: =DASH_FEED!B53 -> 0.744
A14: Mar-26 | B14: ='Monthly IS'!V9 -> 222938 | C14: =DASH_FEED!B54 -> 0.701
A15: Apr-26 | B15: ='Monthly IS'!W9 -> 215423 | C15: =DASH_FEED!B55 -> 0.733
A16: May-26 | B16: ='Monthly IS'!X9 -> 220433 | C16: =DASH_FEED!B56 -> 0.717
A17: Jun-26 | B17: ='Monthly IS'!Y9 -> 212919 | C17: =DASH_FEED!B57 -> 0.74

Sheet Rent Schedule
A1: armanino
A2: Rent Schedule
A3: Illustrative / fictional
A5: Address | B5: Landlord | C5: Related Party | D5: Current Rent (annual) | E5: Term
A6: 120 Meadowbrook Ln, Franklin, TN 37064 | B6: MBK Property Holdings, LLC | C6: Yes | D6: 84000 | E6: 10 years

Sheet Proof of Cash
A1: armanino
A2: Proof of Cash (TTM Jun-26)
A3: Illustrative / fictional
A5: Line | B5: Jul-25 | C5: Aug-25 | D5: Sep-25 | E5: Oct-25 | F5: Nov-25 | G5: Dec-25 | H5: Jan-26 | I5: Feb-26 | J5: Mar-26 | K5: Apr-26 | L5: May-26 | M5: Jun-26
A6: Deposits per Bank | B6: ='Monthly IS'!N9 -> 202899 | C6: ='Monthly IS'!O9 -> 212918 | D6: ='Monthly IS'!P9 -> 207908 | E6: ='Monthly IS'!Q9 -> 220433 | F6: ='Monthly IS'!R9 -> 197889 | G6: ='Monthly IS'!S9 -> 175344 | H6: ='Monthly IS'!T9 -> 205404 | I6: ='Monthly IS'!U9 -> 210413 | ... M6: ='Monthly IS'!Y9 -> 212919
A7: Revenue Collections per P&L | B7: ='Monthly IS'!N9 -> 202899 | C7: ='Monthly IS'!O9 -> 212918 | D7: ='Monthly IS'!P9 -> 207908 | E7: ='Monthly IS'!Q9 -> 220433 | F7: ='Monthly IS'!R9 -> 197889 | G7: ='Monthly IS'!S9 -> 175344 | H7: ='Monthly IS'!T9 -> 205404 | I7: ='Monthly IS'!U9 -> 210413 | ... M7: ='Monthly IS'!Y9 -> 212919
A8: Variance | B8: =B6-B7 -> 0 | C8: =C6-C7 -> 0 | D8: =D6-D7 -> 0 | E8: =E6-E7 -> 0 | F8: =F6-F7 -> 0 | G8: =G6-G7 -> 0 | H8: =H6-H7 -> 0 | I8: =I6-I7 -> 0 | ... M8: =M6-M7 -> 0
A10: Net variance for the twelve months ended Jun-26 | B10: =SUM(B8:M8) -> 0

Sheet Payroll Rec
A1: armanino
A2: Payroll Reconciliation (TTM Jun-26)
A3: Illustrative / fictional
A5: Line | B5: Amount
A6: Wages per Monthly IS (DVM + Staff) | B6: ='Monthly IS'!AA18+'Monthly IS'!AA19 -> 1307120
A7: Wages per Payroll Report | B7: =B6-1500 -> 1305620
A8: Variance | B8: =B6-B7 -> 1500
A10: Minor $1,500 variance noted; immaterial and within tolerance.

Sheet Tax Rec
A1: armanino
A2: Tax Return Reconciliation (FY25)
A3: Illustrative / fictional
A5: Line | B5: Tax Return | C5: Financial Statements | D5: Difference
A6: Revenue | B6: 2469500 | C6: =DASH_FEED!B12 -> 2504921
A7: Reconciling Item — Timing | B7: =C6-B6 -> 35421 | C7: 0
A8: Check | B8: =(B6+B7)-C6 -> 0

Sheet Revenue Series
A1: Revenue Series
A2: Month | B2: Revenue
A3: Jul | B3: ='Monthly IS'!N9 -> 202899
A4: Aug | B4: ='Monthly IS'!O9 -> 212918
A5: Sep | B5: ='Monthly IS'!P9 -> 207908
A6: Oct | B6: ='Monthly IS'!Q9 -> 220433
A7: Nov | B7: ='Monthly IS'!R9 -> 197889
A8: Dec | B8: ='Monthly IS'!S9 -> 175344
A9: Jan | B9: ='Monthly IS'!T9 -> 205404
A10: Feb | B10: ='Monthly IS'!U9 -> 210413
A11: Mar | B11: ='Monthly IS'!V9 -> 222938
A12: Apr | B12: ='Monthly IS'!W9 -> 215423
A13: May | B13: ='Monthly IS'!X9 -> 220433
A14: Jun | B14: ='Monthly IS'!Y9 -> 212919

Sheet Reconciliations
A1: Reconciliations
A2: Name | B2: Variance
A3: Proof of Cash | B3: ='Proof of Cash'!B10 -> 0
A4: Payroll Rec | B4: ='Payroll Rec'!B8 -> 1500
A5: Tax Rec | B5: ='Tax Rec'!B8 -> 0

Sheet Common Size Analysis
A1: Common Size Analysis
A2: Category | B2: Company % | C2: Peer %
A3: Labor - DVM | B3: =DASH_FEED!E46/DASH_FEED!B12 -> 0.21485708 | C3: 0.25
A4: Labor - Staff | B4: =DASH_FEED!E47/DASH_FEED!B12 -> 0.23649448 | C4: 0.285
A5: Labor & Fringe | B5: =DASH_FEED!E48/DASH_FEED!B12 -> 0.06978264 | C5: 0.092
A6: Facility & Equip | B6: =DASH_FEED!E49/DASH_FEED!B12 -> 0.055450851 | C6: 0.08
A7: Admin | B7: =DASH_FEED!E50/DASH_FEED!B12 -> 0.032219379 | C7: 0.045
A8: Fee/Collection | B8: =DASH_FEED!E51/DASH_FEED!B12 -> 0.023234266 | C8: 0.034
A9: Marketing | B9: =DASH_FEED!E52/DASH_FEED!B12 -> 0.0085431836 | C9: 0.01
A11: Peer figures illustrative.
