Workbook

Sheet DASH_FEED
A1: DASH_FEED — Dashboard data feed (edit blue cells only)
A3: [META]
A4: client_name | B4: Meadowbrook Animal Hospital
A5: period_py_label | B5: TTM Jun-25
A6: period_cy_label | B6: TTM Jun-26
A7: purchase_price | B7: 3750000
A8: location | B8: Franklin, Tennessee
A10: [KPIS]
A11: revenue_py | B11: 2410318
A12: revenue_cy | B12: 2504921
A13: cogs_py | B13: 602580
A14: cogs_cy | B14: 651279
A15: adj_ebitda_py | B15: =C33 -> 255490
A16: adj_ebitda_cy | B16: =D33 -> 249035
A17: adj_margin_py | B17: =B15/B11 -> 0.10599846
A18: adj_margin_cy | B18: =B16/B12 -> 0.099418305
A19: implied_multiple_cy | B19: =B7/B16 -> 15.058124
A22: [BRIDGE]
A23: line | B23: ref | C23: value_py | D23: value_cy
A24: Reported EBITDA | C24: 61240 | D24: 38115
A25: Nonrecurring Expenses | B25: A | C25: 38900 | D25: 42350
A26: DVM Compensation | B26: B | C26: 152300 | D26: 168420
A27: Proforma Insurance | B27: C | C27: -4200 | D27: -3850
A28: Rent Normalization | B28: D | C28: -18600 | D28: -6200
A29: Family on Payroll | B29: E | C29: 7450 | D29: 8100
A30: Non-recurring Legal | B30: F | C30: 5600 | D30: 2100
A31: Loss on Disposal | B31: G | C31: 12800 | D31: 0
A32: Seller Adjusted EBITDA | C32: =C24+C25 -> 100140 | D32: =D24+D25 -> 80465
A33: Diligence Adjusted EBITDA | C33: =C32+SUM(C26:C31) -> 255490 | D33: =D32+SUM(D26:D31) -> 249035
A44: [MARGIN_SERIES] | D44: [SGA_MIX]
A45: month | B45: gross_margin_pct | D45: category | E45: adjusted_value_cy
A46: Jul | B46: 0.742 | D46: Labor - DVM | E46: 538200
A47: Aug | B47: 0.718 | D47: Labor - Staff | E47: 592400
A48: Sep | B48: 0.735 | D48: Labor & Fringe | E48: 174800
A49: Oct | B49: 0.709 | D49: Facility & Equip | E49: 138900
A50: Nov | B50: 0.751 | D50: Admin | E50: 84600
A51: Dec | B51: 0.688 | D51: Fee/Collection | E51: 58200
A52: Jan | B52: 0.726 | D52: Marketing | E52: 21400
A53: Feb | B53: 0.744 | D53: D&A | E53: 63100
A54: Mar | B54: 0.701
...

Sheet QofE
A1: armanino
A2: Meadowbrook Animal Hospital — Quality of Earnings
A3: All figures illustrative / fictional
A5: Line | B5: Ref | C5: TTM Jun-25 | D5: TTM Jun-26
A6: Reported EBITDA | C6: =DASH_FEED!C24 -> 61240 | D6: =DASH_FEED!D24 -> 38115
A7: Nonrecurring Expenses | B7: A | C7: =DASH_FEED!C25 -> 38900 | D7: =DASH_FEED!D25 -> 42350
A8: Seller Adjusted EBITDA | C8: =DASH_FEED!C32 -> 100140 | D8: =DASH_FEED!D32 -> 80465
A9: DVM Compensation | B9: B | C9: =DASH_FEED!C26 -> 152300 | D9: =DASH_FEED!D26 -> 168420
A10: Proforma Insurance | B10: C | C10: =DASH_FEED!C27 -> -4200 | D10: =DASH_FEED!D27 -> -3850
A11: Rent Normalization | B11: D | C11: =DASH_FEED!C28 -> -18600 | D11: =DASH_FEED!D28 -> -6200
A12: Family on Payroll | B12: E | C12: =DASH_FEED!C29 -> 7450 | D12: =DASH_FEED!D29 -> 8100
A13: Non-recurring Legal | B13: F | C13: =DASH_FEED!C30 -> 5600 | D13: =DASH_FEED!D30 -> 2100
A14: Loss on Disposal | B14: G | C14: =DASH_FEED!C31 -> 12800 | D14: =DASH_FEED!D31 -> 0
A15: Diligence Adjusted EBITDA | C15: =DASH_FEED!C33 -> 255490 | D15: =DASH_FEED!D33 -> 249035

Sheet Adj FS
A1: armanino
A2: Adjusted Financial Statements
A3: Illustrative / fictional
A5: Metric | B5: TTM Jun-25 | C5: TTM Jun-26
A6: Revenue | B6: =DASH_FEED!B11 -> 2410318 | C6: =DASH_FEED!B12 -> 2504921
A7: Cost of Products | B7: =DASH_FEED!B13 -> 602580 | C7: =DASH_FEED!B14 -> 651279
A8: Gross Profit | B8: =B6-B7 -> 1807738 | C8: =C6-C7 -> 1853642
A9: Diligence Adjusted EBITDA | B9: =DASH_FEED!B15 -> 255490 | C9: =DASH_FEED!B16 -> 249035
A10: Adj. EBITDA Margin | B10: =B9/B6 -> 0.10599846 | C10: =C9/C6 -> 0.099418305

Sheet SG&A
A1: armanino
A2: SG&A — Adjusted Operating Expense Mix (TTM Jun-26)
A3: Illustrative / fictional
A5: Category | B5: Adjusted TTM Jun-26
A6: Labor - DVM | B6: =DASH_FEED!E46 -> 538200
A7: Labor - Staff | B7: =DASH_FEED!E47 -> 592400
A8: Labor & Fringe | B8: =DASH_FEED!E48 -> 174800
A9: Facility & Equip | B9: =DASH_FEED!E49 -> 138900
A10: Admin | B10: =DASH_FEED!E50 -> 84600
A11: Fee/Collection | B11: =DASH_FEED!E51 -> 58200
A12: Marketing | B12: =DASH_FEED!E52 -> 21400
A13: D&A | B13: =DASH_FEED!E53 -> 63100
A14: Total | B14: =SUM(B6:B13) -> 1671600

Sheet Key Findings
A1: armanino
A2: Key Findings
A3: Illustrative / fictional
A5: • Dr. Alicia Monroe (owner) transitions to 21% of production post-close; comp normalized in Adjustment B.
A6: • Gross margin declined ~2.1% Jun-25 to Jun-26, driven by vendor price increases and higher relief-vet usage.
A7: • Buyer valuation revised: FY25 Adjusted EBITDA moved from $300K to $235K after a ~$85K revenue reclassification.
A8: • Cash proof analysis for the twelve months ended Jun-26 nets to a $0 variance.
A9: • Practice offers health and dental; go-forward buyer adds vision and a 2% 401(k) match.
